<?xml version="1.0" encoding="UTF-8"?>
<!-- Generated by org.testng.reporters.JUnitReportReporter -->
<testsuite hostname="LAPTOP-H9MBJ81L" failures="5" tests="26" name="cs265.PizzaHouseSystemTest" time="22.289" errors="0" timestamp="2020-12-14T18:29:31 GMT" skipped="0">
  <testcase classname="cs265.PizzaHouseSystemTest" name="invalidDataTests" time="1.108">
    <failure message="expected:&lt;0&gt; but was:&lt;46&gt;" type="java.lang.AssertionError">
      <![CDATA[java.lang.AssertionError: expected:<0> but was:<46>
at org.testng.AssertJUnit.assertEquals(AssertJUnit.java:115)
at org.testng.AssertJUnit.assertEquals(AssertJUnit.java:125)
at cs265.PizzaHouseSystemTest.TestTemplate(PizzaHouseSystemTest.java:117)
at cs265.PizzaHouseSystemTest.invalidDataTests(PizzaHouseSystemTest.java:132)
at java.base/jdk.internal.reflect.NativeMethodAccessorImpl.invoke0(Native Method)
at java.base/jdk.internal.reflect.NativeMethodAccessorImpl.invoke(NativeMethodAccessorImpl.java:62)
at java.base/jdk.internal.reflect.DelegatingMethodAccessorImpl.invoke(DelegatingMethodAccessorImpl.java:43)
at java.base/java.lang.reflect.Method.invoke(Method.java:564)
at org.testng.internal.MethodInvocationHelper.invokeMethod(MethodInvocationHelper.java:132)
at org.testng.internal.TestInvoker.invokeMethod(TestInvoker.java:599)
at org.testng.internal.TestInvoker.invokeTestMethod(TestInvoker.java:174)
at org.testng.internal.MethodRunner.runInSequence(MethodRunner.java:46)
at org.testng.internal.TestInvoker$MethodInvocationAgent.invoke(TestInvoker.java:822)
at org.testng.internal.TestInvoker.invokeTestMethods(TestInvoker.java:147)
at org.testng.internal.TestMethodWorker.invokeTestMethods(TestMethodWorker.java:146)
at org.testng.internal.TestMethodWorker.run(TestMethodWorker.java:128)
at java.base/java.util.ArrayList.forEach(ArrayList.java:1511)
at org.testng.TestRunner.privateRun(TestRunner.java:764)
at org.testng.TestRunner.run(TestRunner.java:585)
at org.testng.SuiteRunner.runTest(SuiteRunner.java:384)
at org.testng.SuiteRunner.runSequentially(SuiteRunner.java:378)
at org.testng.SuiteRunner.privateRun(SuiteRunner.java:337)
at org.testng.SuiteRunner.run(SuiteRunner.java:286)
at org.testng.SuiteRunnerWorker.runSuite(SuiteRunnerWorker.java:53)
at org.testng.SuiteRunnerWorker.run(SuiteRunnerWorker.java:96)
at org.testng.TestNG.runSuitesSequentially(TestNG.java:1218)
at org.testng.TestNG.runSuitesLocally(TestNG.java:1140)
at org.testng.TestNG.runSuites(TestNG.java:1069)
at org.testng.TestNG.run(TestNG.java:1037)
at org.testng.remote.AbstractRemoteTestNG.run(AbstractRemoteTestNG.java:115)
at org.testng.remote.RemoteTestNG.initAndRun(RemoteTestNG.java:251)
at org.testng.remote.RemoteTestNG.main(RemoteTestNG.java:77)
]]>
    </failure>
  </testcase> <!-- invalidDataTests -->
  <system-out/>
  <testcase classname="cs265.PizzaHouseSystemTest" name="validDataTests" time="0.780"/>
  <system-out/>
  <testcase classname="cs265.PizzaHouseSystemTest" name="invalidDataTests" time="0.782"/>
  <system-out/>
  <testcase classname="cs265.PizzaHouseSystemTest" name="invalidDataTests" time="0.829"/>
  <system-out/>
  <testcase classname="cs265.PizzaHouseSystemTest" name="validDataTests" time="0.834"/>
  <system-out/>
  <testcase classname="cs265.PizzaHouseSystemTest" name="validDataTests" time="1.102"/>
  <system-out/>
  <testcase classname="cs265.PizzaHouseSystemTest" name="invalidDataTests" time="0.828">
    <failure message="expected:&lt;0&gt; but was:&lt;45&gt;" type="java.lang.AssertionError">
      <![CDATA[java.lang.AssertionError: expected:<0> but was:<45>
at org.testng.AssertJUnit.assertEquals(AssertJUnit.java:115)
at org.testng.AssertJUnit.assertEquals(AssertJUnit.java:125)
at cs265.PizzaHouseSystemTest.TestTemplate(PizzaHouseSystemTest.java:117)
at cs265.PizzaHouseSystemTest.invalidDataTests(PizzaHouseSystemTest.java:132)
at java.base/jdk.internal.reflect.NativeMethodAccessorImpl.invoke0(Native Method)
at java.base/jdk.internal.reflect.NativeMethodAccessorImpl.invoke(NativeMethodAccessorImpl.java:62)
at java.base/jdk.internal.reflect.DelegatingMethodAccessorImpl.invoke(DelegatingMethodAccessorImpl.java:43)
at java.base/java.lang.reflect.Method.invoke(Method.java:564)
at org.testng.internal.MethodInvocationHelper.invokeMethod(MethodInvocationHelper.java:132)
at org.testng.internal.TestInvoker.invokeMethod(TestInvoker.java:599)
at org.testng.internal.TestInvoker.invokeTestMethod(TestInvoker.java:174)
at org.testng.internal.MethodRunner.runInSequence(MethodRunner.java:46)
at org.testng.internal.TestInvoker$MethodInvocationAgent.invoke(TestInvoker.java:822)
at org.testng.internal.TestInvoker.invokeTestMethods(TestInvoker.java:147)
at org.testng.internal.TestMethodWorker.invokeTestMethods(TestMethodWorker.java:146)
at org.testng.internal.TestMethodWorker.run(TestMethodWorker.java:128)
at java.base/java.util.ArrayList.forEach(ArrayList.java:1511)
at org.testng.TestRunner.privateRun(TestRunner.java:764)
at org.testng.TestRunner.run(TestRunner.java:585)
at org.testng.SuiteRunner.runTest(SuiteRunner.java:384)
at org.testng.SuiteRunner.runSequentially(SuiteRunner.java:378)
at org.testng.SuiteRunner.privateRun(SuiteRunner.java:337)
at org.testng.SuiteRunner.run(SuiteRunner.java:286)
at org.testng.SuiteRunnerWorker.runSuite(SuiteRunnerWorker.java:53)
at org.testng.SuiteRunnerWorker.run(SuiteRunnerWorker.java:96)
at org.testng.TestNG.runSuitesSequentially(TestNG.java:1218)
at org.testng.TestNG.runSuitesLocally(TestNG.java:1140)
at org.testng.TestNG.runSuites(TestNG.java:1069)
at org.testng.TestNG.run(TestNG.java:1037)
at org.testng.remote.AbstractRemoteTestNG.run(AbstractRemoteTestNG.java:115)
at org.testng.remote.RemoteTestNG.initAndRun(RemoteTestNG.java:251)
at org.testng.remote.RemoteTestNG.main(RemoteTestNG.java:77)
]]>
    </failure>
  </testcase> <!-- invalidDataTests -->
  <system-out/>
  <testcase classname="cs265.PizzaHouseSystemTest" name="validDataTests" time="0.805"/>
  <system-out/>
  <testcase classname="cs265.PizzaHouseSystemTest" name="invalidDataTests" time="0.793">
    <failure message="expected:&lt;0&gt; but was:&lt;31&gt;" type="java.lang.AssertionError">
      <![CDATA[java.lang.AssertionError: expected:<0> but was:<31>
at org.testng.AssertJUnit.assertEquals(AssertJUnit.java:115)
at org.testng.AssertJUnit.assertEquals(AssertJUnit.java:125)
at cs265.PizzaHouseSystemTest.TestTemplate(PizzaHouseSystemTest.java:117)
at cs265.PizzaHouseSystemTest.invalidDataTests(PizzaHouseSystemTest.java:132)
at java.base/jdk.internal.reflect.NativeMethodAccessorImpl.invoke0(Native Method)
at java.base/jdk.internal.reflect.NativeMethodAccessorImpl.invoke(NativeMethodAccessorImpl.java:62)
at java.base/jdk.internal.reflect.DelegatingMethodAccessorImpl.invoke(DelegatingMethodAccessorImpl.java:43)
at java.base/java.lang.reflect.Method.invoke(Method.java:564)
at org.testng.internal.MethodInvocationHelper.invokeMethod(MethodInvocationHelper.java:132)
at org.testng.internal.TestInvoker.invokeMethod(TestInvoker.java:599)
at org.testng.internal.TestInvoker.invokeTestMethod(TestInvoker.java:174)
at org.testng.internal.MethodRunner.runInSequence(MethodRunner.java:46)
at org.testng.internal.TestInvoker$MethodInvocationAgent.invoke(TestInvoker.java:822)
at org.testng.internal.TestInvoker.invokeTestMethods(TestInvoker.java:147)
at org.testng.internal.TestMethodWorker.invokeTestMethods(TestMethodWorker.java:146)
at org.testng.internal.TestMethodWorker.run(TestMethodWorker.java:128)
at java.base/java.util.ArrayList.forEach(ArrayList.java:1511)
at org.testng.TestRunner.privateRun(TestRunner.java:764)
at org.testng.TestRunner.run(TestRunner.java:585)
at org.testng.SuiteRunner.runTest(SuiteRunner.java:384)
at org.testng.SuiteRunner.runSequentially(SuiteRunner.java:378)
at org.testng.SuiteRunner.privateRun(SuiteRunner.java:337)
at org.testng.SuiteRunner.run(SuiteRunner.java:286)
at org.testng.SuiteRunnerWorker.runSuite(SuiteRunnerWorker.java:53)
at org.testng.SuiteRunnerWorker.run(SuiteRunnerWorker.java:96)
at org.testng.TestNG.runSuitesSequentially(TestNG.java:1218)
at org.testng.TestNG.runSuitesLocally(TestNG.java:1140)
at org.testng.TestNG.runSuites(TestNG.java:1069)
at org.testng.TestNG.run(TestNG.java:1037)
at org.testng.remote.AbstractRemoteTestNG.run(AbstractRemoteTestNG.java:115)
at org.testng.remote.RemoteTestNG.initAndRun(RemoteTestNG.java:251)
at org.testng.remote.RemoteTestNG.main(RemoteTestNG.java:77)
]]>
    </failure>
  </testcase> <!-- invalidDataTests -->
  <system-out/>
  <testcase classname="cs265.PizzaHouseSystemTest" name="validDataTests" time="0.781"/>
  <system-out/>
  <testcase classname="cs265.PizzaHouseSystemTest" name="validDataTests" time="1.093"/>
  <system-out/>
  <testcase classname="cs265.PizzaHouseSystemTest" name="validDataTests" time="0.801"/>
  <system-out/>
  <testcase classname="cs265.PizzaHouseSystemTest" name="validDataTests" time="0.776"/>
  <system-out/>
  <testcase classname="cs265.PizzaHouseSystemTest" name="validDataTests" time="0.830"/>
  <system-out/>
  <testcase classname="cs265.PizzaHouseSystemTest" name="invalidDataTests" time="0.812"/>
  <system-out/>
  <testcase classname="cs265.PizzaHouseSystemTest" name="invalidDataTests" time="0.805"/>
  <system-out/>
  <testcase classname="cs265.PizzaHouseSystemTest" name="validDataTests" time="0.776"/>
  <system-out/>
  <testcase classname="cs265.PizzaHouseSystemTest" name="validDataTests" time="1.063"/>
  <system-out/>
  <testcase classname="cs265.PizzaHouseSystemTest" name="invalidDataTests" time="0.790"/>
  <system-out/>
  <testcase classname="cs265.PizzaHouseSystemTest" name="invalidDataTests" time="0.803">
    <failure message="expected:&lt;0&gt; but was:&lt;30&gt;" type="java.lang.AssertionError">
      <![CDATA[java.lang.AssertionError: expected:<0> but was:<30>
at org.testng.AssertJUnit.assertEquals(AssertJUnit.java:115)
at org.testng.AssertJUnit.assertEquals(AssertJUnit.java:125)
at cs265.PizzaHouseSystemTest.TestTemplate(PizzaHouseSystemTest.java:117)
at cs265.PizzaHouseSystemTest.invalidDataTests(PizzaHouseSystemTest.java:132)
at java.base/jdk.internal.reflect.NativeMethodAccessorImpl.invoke0(Native Method)
at java.base/jdk.internal.reflect.NativeMethodAccessorImpl.invoke(NativeMethodAccessorImpl.java:62)
at java.base/jdk.internal.reflect.DelegatingMethodAccessorImpl.invoke(DelegatingMethodAccessorImpl.java:43)
at java.base/java.lang.reflect.Method.invoke(Method.java:564)
at org.testng.internal.MethodInvocationHelper.invokeMethod(MethodInvocationHelper.java:132)
at org.testng.internal.TestInvoker.invokeMethod(TestInvoker.java:599)
at org.testng.internal.TestInvoker.invokeTestMethod(TestInvoker.java:174)
at org.testng.internal.MethodRunner.runInSequence(MethodRunner.java:46)
at org.testng.internal.TestInvoker$MethodInvocationAgent.invoke(TestInvoker.java:822)
at org.testng.internal.TestInvoker.invokeTestMethods(TestInvoker.java:147)
at org.testng.internal.TestMethodWorker.invokeTestMethods(TestMethodWorker.java:146)
at org.testng.internal.TestMethodWorker.run(TestMethodWorker.java:128)
at java.base/java.util.ArrayList.forEach(ArrayList.java:1511)
at org.testng.TestRunner.privateRun(TestRunner.java:764)
at org.testng.TestRunner.run(TestRunner.java:585)
at org.testng.SuiteRunner.runTest(SuiteRunner.java:384)
at org.testng.SuiteRunner.runSequentially(SuiteRunner.java:378)
at org.testng.SuiteRunner.privateRun(SuiteRunner.java:337)
at org.testng.SuiteRunner.run(SuiteRunner.java:286)
at org.testng.SuiteRunnerWorker.runSuite(SuiteRunnerWorker.java:53)
at org.testng.SuiteRunnerWorker.run(SuiteRunnerWorker.java:96)
at org.testng.TestNG.runSuitesSequentially(TestNG.java:1218)
at org.testng.TestNG.runSuitesLocally(TestNG.java:1140)
at org.testng.TestNG.runSuites(TestNG.java:1069)
at org.testng.TestNG.run(TestNG.java:1037)
at org.testng.remote.AbstractRemoteTestNG.run(AbstractRemoteTestNG.java:115)
at org.testng.remote.RemoteTestNG.initAndRun(RemoteTestNG.java:251)
at org.testng.remote.RemoteTestNG.main(RemoteTestNG.java:77)
]]>
    </failure>
  </testcase> <!-- invalidDataTests -->
  <system-out/>
  <testcase classname="cs265.PizzaHouseSystemTest" name="invalidDataTests" time="1.104"/>
  <system-out/>
  <testcase classname="cs265.PizzaHouseSystemTest" name="validDataTests" time="0.781"/>
  <system-out/>
  <testcase classname="cs265.PizzaHouseSystemTest" name="validDataTests" time="0.809"/>
  <system-out/>
  <testcase classname="cs265.PizzaHouseSystemTest" name="validDataTests" time="0.824"/>
  <system-out/>
  <testcase classname="cs265.PizzaHouseSystemTest" name="validDataTests" time="0.803"/>
  <system-out/>
  <testcase classname="cs265.PizzaHouseSystemTest" name="validDataTests" time="0.777">
    <failure message="expected:&lt;50&gt; but was:&lt;51&gt;" type="java.lang.AssertionError">
      <![CDATA[java.lang.AssertionError: expected:<50> but was:<51>
at org.testng.AssertJUnit.assertEquals(AssertJUnit.java:115)
at org.testng.AssertJUnit.assertEquals(AssertJUnit.java:125)
at cs265.PizzaHouseSystemTest.TestTemplate(PizzaHouseSystemTest.java:117)
at cs265.PizzaHouseSystemTest.validDataTests(PizzaHouseSystemTest.java:125)
at java.base/jdk.internal.reflect.NativeMethodAccessorImpl.invoke0(Native Method)
at java.base/jdk.internal.reflect.NativeMethodAccessorImpl.invoke(NativeMethodAccessorImpl.java:62)
at java.base/jdk.internal.reflect.DelegatingMethodAccessorImpl.invoke(DelegatingMethodAccessorImpl.java:43)
at java.base/java.lang.reflect.Method.invoke(Method.java:564)
at org.testng.internal.MethodInvocationHelper.invokeMethod(MethodInvocationHelper.java:132)
at org.testng.internal.TestInvoker.invokeMethod(TestInvoker.java:599)
at org.testng.internal.TestInvoker.invokeTestMethod(TestInvoker.java:174)
at org.testng.internal.MethodRunner.runInSequence(MethodRunner.java:46)
at org.testng.internal.TestInvoker$MethodInvocationAgent.invoke(TestInvoker.java:822)
at org.testng.internal.TestInvoker.invokeTestMethods(TestInvoker.java:147)
at org.testng.internal.TestMethodWorker.invokeTestMethods(TestMethodWorker.java:146)
at org.testng.internal.TestMethodWorker.run(TestMethodWorker.java:128)
at java.base/java.util.ArrayList.forEach(ArrayList.java:1511)
at org.testng.TestRunner.privateRun(TestRunner.java:764)
at org.testng.TestRunner.run(TestRunner.java:585)
at org.testng.SuiteRunner.runTest(SuiteRunner.java:384)
at org.testng.SuiteRunner.runSequentially(SuiteRunner.java:378)
at org.testng.SuiteRunner.privateRun(SuiteRunner.java:337)
at org.testng.SuiteRunner.run(SuiteRunner.java:286)
at org.testng.SuiteRunnerWorker.runSuite(SuiteRunnerWorker.java:53)
at org.testng.SuiteRunnerWorker.run(SuiteRunnerWorker.java:96)
at org.testng.TestNG.runSuitesSequentially(TestNG.java:1218)
at org.testng.TestNG.runSuitesLocally(TestNG.java:1140)
at org.testng.TestNG.runSuites(TestNG.java:1069)
at org.testng.TestNG.run(TestNG.java:1037)
at org.testng.remote.AbstractRemoteTestNG.run(AbstractRemoteTestNG.java:115)
at org.testng.remote.RemoteTestNG.initAndRun(RemoteTestNG.java:251)
at org.testng.remote.RemoteTestNG.main(RemoteTestNG.java:77)
]]>
    </failure>
  </testcase> <!-- validDataTests -->
  <system-out/>
</testsuite> <!-- cs265.PizzaHouseSystemTest -->
